Workbook

Sheet Sheet1
A1: Price | I1: log return | P1: Annual Returns and Annual volatilities | X1: Minimum Volatility Portfolio
A2: Date | B2: AAPL | C2: NVDA | D2: TSLA | E2: BKR | F2: CSX | G2: S&P500 | I2: AAPL | J2: NVDA | K2: TSLA | L2: BKR | M2: CSX | N2: S&P500 | Q2: AAPL | R2: NVDA | S2: TSLA | T2: BKR | U2: CSX | V2: S&P500 | AF2: Risk Free Return | AH2: 0.0404
A3: 46030 | B3: 259.04 | C3: 185.04 | D3: 435.8 | E3: 50.2 | F3: 35.32 | G3: 6921.46 | I3: =LN(B3/B4) -> -0.0049675671 | J3: =LN(C3/C4) -> -0.021756838 | K3: =LN(D3/D4) -> 0.010124508 | L3: =LN(E3/E4) -> 0.027465377 | M3: =LN(F3/F4) -> 0.0076737623 | N3: =LN(G3/G4) -> 7.6576372e-05 | P3: Daily Returns | Q3: =AVERAGE(I3:I754) -> 0.00091528572 | R3: =AVERAGE(J3:J754) -> 0.0032864094 | S3: =AVERAGE(K3:K754) -> 0.0017175667 | T3: =AVERAGE(L3:L754) -> 0.00066087464 | U3: =AVERAGE(M3:M754) -> 0.00012546279 | V3: =AVERAGE(N3:N754) -> 0.0007655325 | Y3: AAPL | Z3: NVDA | AA3: TSLA | AB3: BKR | AC3: CSX | AK3: AAPL | AL3: NVDA | AM3: TSLA | AN3: BKR | AO3: CSX | AP3: S&P500
A4: 46029 | B4: 260.33 | C4: 189.11 | D4: 431.41 | E4: 48.84 | F4: 35.05 | G4: 6920.93 | I4: =LN(B4/B5) -> -0.0077675494 | J4: =LN(C4/C5) -> 0.0099376399 | K4: =LN(D4/D5) -> -0.003586431 | L4: =LN(E4/E5) -> -0.010995835 | M4: =LN(F4/F5) -> -0.028685881 | N4: =LN(G4/G5) -> -0.0034459043 | P4: Annual Returns | Q4: =Q3*252 -> 0.230652 | R4: =R3*252 -> 0.82817517 | S4: =S3*252 -> 0.43282682 | T4: =T3*252 -> 0.16654041 | U4: =U3*252 -> 0.031616622 | V4: =V3*252 -> 0.19291419 | X4: weights (with short-selling) | Y4: 0.3140496 | Z4: 0.021565859 | AA4: 0 | AB4: 0.16472597 | AC4: 0.49965857 | AD4: =SUM(Y4:AC4) -> 1 | AJ4: Annual Returns | AK4: 0.230652 | AL4: 0.82817517 | AM4: 0.43282682 | AN4: 0.16654041 | AO4: 0.031616622 | AP4: 0.19291419
A5: 46028 | B5: 262.36 | C5: 187.24 | D5: 432.96 | E5: 49.38 | F5: 36.07 | G5: 6944.82 | I5: =LN(B5/B6) -> -0.018504361 | J5: =LN(C5/C6) -> -0.0046888406 | K5: =LN(D5/D6) -> -0.04230648 | L5: =LN(E5/E6) -> 0.0062976338 | M5: =LN(F5/F6) -> 0.0044456867 | N5: =LN(G5/G6) -> 0.006177589 | P5: Daily Volatility | Q5: =STDEV(I3:I754) -> 0.015980678 | R5: =STDEV(J3:J754) -> 0.031129773 | S5: =STDEV(K3:K754) -> 0.037424172 | T5: =STDEV(L3:L754) -> 0.019127605 | U5: =STDEV(M3:M754) -> 0.013711553 | V5: =STDEV(N3:N754) -> 0.0094196183 | X5: weights (without short-selling) | Y5: 0.31404933 | Z5: 0.021565962 | AA5: 0 | AB5: 0.16472625 | AC5: 0.49965846 | AD5: =SUM(Y5:AC5) -> 1 | AJ5: Annual Volatility | AK5: 0.2536854 | AL5: 0.49416983 | AM5: 0.59409031 | AN5: 0.30364131 | AO5: 0.21766415 | AP5: 0.15311405
A6: 46027 | B6: 267.26 | C6: 188.12 | D6: 451.67 | E6: 49.07 | F6: 35.91 | G6: 6902.05 | I6: =LN(B6/B7) -> -0.013933753 | J6: =LN(C6/C7) -> -0.0038729921 | K6: =LN(D6/D7) -> 0.03057311 | L6: =LN(E6/E7) -> 0.040125953 | M6: =LN(F6/F7) -> -0.0099751451 | N6: =LN(G6/G7) -> 0.0063340841 | P6: Annual Volatility | Q6: =SQRT(252)*Q5 -> 0.2536854 | R6: =SQRT(252)*R5 -> 0.49416983 | S6: =SQRT(252)*S5 -> 0.59409031 | T6: =SQRT(252)*T5 -> 0.30364131 | U6: =SQRT(252)*U5 -> 0.21766415 | V6: =SQRT(252)*V5 -> 0.14953181 | AJ6: Beta | AK6: =V20/V25 -> 1.1561863 | AL6: =V21/V25 -> 2.1325124 | AM6: =V22/V25 -> 2.3076776 | AN6: =V23/V25 -> 1.0041814 | AO6: =V24/V25 -> 0.73127609 | AP6: =V25/V25 -> 1
A7: 46024 | B7: 271.01 | C7: 188.85 | D7: 438.07 | E7: 47.14 | F7: 36.27 | G7: 6858.47 | I7: =LN(B7/B8) -> -0.0031315073 | J7: =LN(C7/C8) -> 0.01252181 | K7: =LN(D7/D8) -> -0.026246452 | L7: =LN(E7/E8) -> 0.034530837 | M7: =LN(F7/F8) -> 0.00055157199 | N7: =LN(G7/G8) -> 0.0018928827 | X7: with short-selling | AA7: without short-selling | AJ7: CAPM(Expected Returns) | AK7: =($AP$4-$AH$2)*AK6+$AH$2 -> 0.21673482 | AL7: =($AP$4-$AH$2)*AL6+$AH$2 -> 0.3656384 | AM7: =($AP$4-$AH$2)*AM6+$AH$2 -> 0.39235359 | AN7: =($AP$4-$AH$2)*AN6+$AH$2 -> 0.19355192 | AO7: =($AP$4-$AH$2)*AO6+$AH$2 -> 0.15192998
A8: 46022 | B8: 271.86 | C8: 186.5 | D8: 449.72 | E8: 45.54 | F8: 36.25 | G8: 6845.5 | I8: =LN(B8/B9) -> -0.0044775646 | J8: =LN(C8/C9) -> -0.0055609169 | K8: =LN(D8/D9) -> -0.010418719 | L8: =LN(E8/E9) -> -0.012004946 | M8: =LN(F8/F9) -> -0.004678693 | N8: =LN(G8/G9) -> -0.0073848334 | X8: Portfolio Variance | Y8: {=MMULT(Y4:AC4,MMULT(Q20:U24,TRANSPOSE(Y4:AC4)))} -> 0.033221607 | AA8: Portfolio Variance | AB8: {=MMULT(Y5:AC5,MMULT(Q20:U24,TRANSPOSE(Y5:AC5)))} -> 0.033221607 | AJ8: Jensen’s Alpha. | AK8: =AK4-AK7 -> 0.013917177 | AL8: =AL4-AL7 -> 0.46253677 | AM8: =AM4-AM7 -> 0.040473232 | AN8: =AN4-AN7 -> -0.027011512 | AO8: =AO4-AO7 -> -0.12031336
A9: 46021 | B9: 273.08 | C9: 187.54 | D9: 454.43 | E9: 46.09 | F9: 36.42 | G9: 6896.24 | I9: =LN(B9/B10) -> -0.0024870176 | J9: =LN(C9/C10) -> -0.0036193354 | K9: =LN(D9/D10) -> -0.011399688 | L9: =LN(E9/E10) -> 0.015524527 | M9: =LN(F9/F10) -> -0.0082034915 | N9: =LN(G9/G10) -> -0.0013766143 | P9: Daily covariance | X9: Portfolio Volatility | Y9: =SQRT(Y8) -> 0.18226795 | AA9: Portfolio Volatility | AB9: =SQRT(AB8) -> 0.18226795 | AJ9: Systematic Risk | AK9: =AK6*$AP$5 -> 0.17702838 | AL9: =AL6*$AP$5 -> 0.32651762 | AM9: =AM6*$AP$5 -> 0.35333788 | AN9: =AN6*$AP$5 -> 0.15375429 | AO9: =AO6*$AP$5 -> 0.11196865
A10: 46020 | B10: 273.76 | C10: 188.22 | D10: 459.64 | E10: 45.38 | F10: 36.72 | G10: 6905.74 | I10: =LN(B10/B11) -> 0.0013158859 | J10: =LN(C10/C11) -> -0.012198171 | K10: =LN(D10/D11) -> -0.03327115 | L10: =LN(E10/E11) -> 0.0028688092 | M10: =LN(F10/F11) -> 0.0027270265 | N10: =LN(G10/G11) -> -0.0034982053 | Q10: AAPL | R10: NVDA | S10: TSLA | T10: BKR | U10: CSX | V10: S&P500 | X10: Total Return | Y10: =SUMPRODUCT(Q4:U4,Y4:AC4) -> 0.13352752 | AA10: Total Return | AB10: =SUMPRODUCT(Q4:U4,Y5:AC5) -> 0.13352759 | AJ10: Idiosyncratic Risk | AK10: =AK5-AK9 -> 0.076657026 | AL10: =AL5-AL9 -> 0.16765221 | AM10: =AM5-AM9 -> 0.24075243 | AN10: =AN5-AN9 -> 0.14988702 | AO10: =AO5-AO9 -> 0.10569551
A11: 46017 | B11: 273.4 | C11: 190.53 | D11: 475.19 | E11: 45.25 | F11: 36.62 | G11: 6929.94 | I11: =LN(B11/B12) -> -0.0014985109 | J11: =LN(C11/C12) -> 0.010128271 | K11: =LN(D11/D12) -> -0.021258569 | L11: =LN(E11/E12) -> -0.0011043623 | M11: =LN(F11/F12) -> -0.0043596799 | N11: =LN(G11/G12) -> -0.0003044296 | P11: AAPL | Q11: =VARP(Sheet1!$I$3:$I$754) -> 0.00025504247 | R11: 0.00018278924 | S11: 0.00026089062 | T11: 7.8156725e-05 | U11: 6.988649e-05 | V11: 0.00010245108 | X11: Excess Return | Y11: =Y10-AH2 -> 0.093127524 | AA11: Excess Return | AB11: =AB10-AH2 -> 0.09312759
A12: 46015 | B12: 273.81 | C12: 188.61 | D12: 485.4 | E12: 45.3 | F12: 36.78 | G12: 6932.05 | I12: =LN(B12/B13) -> 0.0053097146 | J12: =LN(C12/C13) -> -0.0031761183 | K12: =LN(D12/D13) -> -0.00032957074 | L12: =LN(E12/E13) -> 0.0024312091 | M12: =LN(F12/F13) -> 0.0051792401 | N12: =LN(G12/G13) -> 0.0032163382 | P12: NVDA | Q12: 0.00018278924 | R12: =VARP(Sheet1!$J$3:$J$754) -> 0.00096777414 | S12: 0.00043794762 | T12: 0.00012443069 | U12: 6.6163089e-05 | V12: 0.00018896452 | X12: Sharp Ratio | Y12: =Y11/Y9 -> 0.51093745 | AA12: Sharp Ratio | AB12: =AB11/AB9 -> 0.51093781
A13: 46014 | B13: 272.36 | C13: 189.21 | D13: 485.56 | E13: 45.19 | F13: 36.59 | G13: 6909.79 | I13: =LN(B13/B14) -> 0.005116607 | J13: =LN(C13/C14) -> 0.029607955 | K13: =LN(D13/D14) -> -0.0065073257 | L13: =LN(E13/E14) -> -0.0081543152 | M13: =LN(F13/F14) -> 0.0013674281 | N13: =LN(G13/G14) -> 0.0045400955 | P13: TSLA | Q13: 0.00026089062 | R13: 0.00043794762 | S13: =VARP(Sheet1!$K$3:$K$754) -> 0.0013987062 | T13: 0.00018660145 | U13: 9.708844e-05 | V13: 0.00020448613
A14: 46013 | B14: 270.97 | C14: 183.69 | D14: 488.73 | E14: 45.56 | F14: 36.54 | G14: 6878.49 | I14: =LN(B14/B15) -> -0.0099148873 | J14: =LN(C14/C15) -> 0.014807773 | K14: =LN(D14/D15) -> 0.015527206 | L14: =LN(E14/E15) -> 0.018832948 | M14: =LN(F14/F15) -> 0.0010952904 | N14: =LN(G14/G15) -> 0.0064158365 | P14: BKR | Q14: 7.8156725e-05 | R14: 0.00012443069 | S14: 0.00018660145 | T14: =VARP(Sheet1!$L$3:$L$754) -> 0.00036537875 | U14: 8.8892246e-05 | V14: 8.8981742e-05 | AM14: Beta | AN14: CAPM{E(R)} | AO14: Jensen’s Alpha | AQ14: Systematic Risk | AR14: Idiosyncratic Risk
A15: 46010 | B15: 273.67 | C15: 180.99 | D15: 481.2 | E15: 44.71 | F15: 36.5 | G15: 6834.5 | I15: =LN(B15/B16) -> 0.0054226491 | J15: =LN(C15/C16) -> 0.038582208 | K15: =LN(D15/D16) -> -0.0044994218 | L15: =LN(E15/E16) -> 0.0053823857 | M15: =LN(F15/F16) -> -0.0030091665 | N15: =LN(G15/G16) -> 0.0087793728 | P15: CSX | Q15: 6.988649e-05 | R15: 6.6163089e-05 | S15: 9.708844e-05 | T15: 8.8892246e-05 | U15: =VARP(Sheet1!$M$3:$M$754) -> 0.00018775667 | V15: 6.4799266e-05 | X15: Maximum Sharp Ratio Volatility Portfolio | AJ15: Min. Volatility Portfolio(with short-selling) | AM15: =SUMPRODUCT(AK6:AO6,Y4:AC4) -> 0.93989245 | AN15: =($AP$4-$AH$2)*AM15+$AH$2 -> 0.18374694 | AO15: =Y10-AN15 -> -0.050219412 | AQ15: =$AP$5*AM15 -> 0.14391074 | AR15: =Y9-AQ15 -> 0.038357212
A16: 46009 | B16: 272.19 | C16: 174.14 | D16: 483.37 | E16: 44.47 | F16: 36.61 | G16: 6774.76 | I16: =LN(B16/B17) -> 0.0012866939 | J16: =LN(C16/C17) -> 0.018546956 | K16: =LN(D16/D17) -> 0.033896558 | L16: =LN(E16/E17) -> -0.018271453 | M16: =LN(F16/F17) -> 0.0030091665 | N16: =LN(G16/G17) -> 0.0079030123 | P16: S&P500 | Q16: 0.00010245108 | R16: 0.00018896452 | S16: 0.00020448613 | T16: 8.8981742e-05 | U16: 6.4799266e-05 | V16: =VARP(Sheet1!$N$3:$N$754) -> 8.8611219e-05 | AJ16: Min. Volatility Portfolio(without short-selling) | AM16: =SUMPRODUCT(AK6:AO6,Y5:AC5) -> 0.93989255 | AN16: =($AP$4-$AH$2)*AM16+$AH$2 -> 0.18374695 | AO16: =AB10-AN16 -> -0.050219362 | AQ16: =$AP$5*AM16 -> 0.14391076 | AR16: =AB9-AQ16 -> 0.038357196
A17: 46008 | B17: 271.84 | C17: 170.94 | D17: 467.26 | E17: 45.29 | F17: 36.5 | G17: 6721.43 | I17: =LN(B17/B18) -> -0.010138251 | J17: =LN(C17/C18) -> -0.03889666 | K17: =LN(D17/D18) -> -0.047274615 | L17: =LN(E17/E18) -> 0.0059794221 | M17: =LN(F17/F18) -> -0.0081855846 | N17: =LN(G17/G18) -> -0.011659917 | Y17: AAPL | Z17: NVDA | AA17: TSLA | AB17: BKR | AC17: CSX | AJ17: Max. Sharp Ratio Portfolio(with short-selling) | AM17: =SUMPRODUCT(AK6:AO6,Y18:AC18) -> 1.9094978 | AN17: =($AP$4-$AH$2)*AM17+$AH$2 -> 0.33162551 | AO17: =Y24-AN17 -> 0.36132277 | AQ17: =$AP$5*AM17 -> 0.29237095 | AR17: =Y23-AQ17 -> 0.11403714
A18: 46007 | B18: 274.61 | C18: 177.72 | D18: 489.88 | E18: 45.02 | F18: 36.8 | G18: 6800.26 | I18: =LN(B18/B19) -> 0.0018224236 | J18: =LN(C18/C19) -> 0.0080789118 | K18: =LN(D18/D19) -> 0.03019324 | L18: =LN(E18/E19) -> -0.040697598 | M18: =LN(F18/F19) -> -0.010273137 | N18: =LN(G18/G19) -> -0.0023867639 | P18: Annual Covariance | X18: weights (with short-selling) | Y18: 0.17803672 | Z18: 0.77836547 | AA18: 0 | AB18: 0.043597839 | AC18: 0 | AD18: =SUM(Y18:AC18) -> 1 | AJ18: Max. Sharp Ratio Portfolio(without short-selling) | AM18: =SUMPRODUCT(AK6:AO6,Y19:AC19) -> 1.7830004 | AN18: =($AP$4-$AH$2)*AM18+$AH$2 -> 0.31233287 | AO18: =AB24-AN18 -> 0.30376848 | AQ18: =$AP$5*AM18 -> 0.27300242 | AR18: =AB23-AQ18 -> 0.086830575
A19: 46006 | B19: 274.11 | C19: 176.29 | D19: 475.31 | E19: 46.89 | F19: 37.18 | G19: 6816.51 | I19: =LN(B19/B20) -> -0.015098315 | J19: =LN(C19/C20) -> 0.0072301132 | K19: =LN(D19/D20) -> 0.035004162 | L19: =LN(E19/E20) -> 0.00064000002 | M19: =LN(F19/F20) -> -0.0056323067 | N19: =LN(G19/G20) -> -0.0015977816 | Q19: AAPL | R19: NVDA | S19: TSLA | T19: BKR | U19: CSX | V19: S&P500 | X19: weights (without short-selling) | Y19: 0.24868257 | Z19: 0.65464299 | AA19: 0.0018136551 | AB19: 0.094860772 | AC19: 0 | AD19: =SUM(Y19:AC19) -> 0.99999998 | AJ19: Equal-Weighted Portfolio (benchmark) | AM19: =SUMPRODUCT(AK6:AO6,Y31:AC31) -> 1.4663668 | AN19: =($AP$4-$AH$2)*AM19+$AH$2 -> 0.26404174 | AO19: =Y36-AN19 -> 0.073920461 | AQ19: =$AP$5*AM19 -> 0.22452136 | AR19: =Y35-AQ19 -> 0.028682789
A20: 46003 | B20: 278.28 | C20: 175.02 | D20: 458.96 | E20: 46.86 | F20: 37.39 | G20: 6827.41 | I20: =LN(B20/B21) -> 0.00089877952 | J20: =LN(C20/C21) -> -0.033209963 | K20: =LN(D20/D21) -> 0.026650581 | L20: =LN(E20/E21) -> -0.012722818 | M20: =LN(F20/F21) -> 0.0064395178 | N20: =LN(G20/G21) -> -0.010720936 | P20: AAPL | Q20: {=Q11:V16*252} -> 0.064270704 | R20: 0.046062889 | S20: 0.065744437 | T20: 0.019695495 | U20: 0.017611395 | V20: 0.025817672
A21: 46002 | B21: 278.03 | C21: 180.93 | D21: 446.89 | E21: 47.46 | F21: 37.15 | G21: 6901 | I21: =LN(B21/B22) -> -0.0026939188 | J21: =LN(C21/C22) -> -0.015629174 | K21: =LN(D21/D22) -> -0.010152145 | L21: =LN(E21/E22) -> -0.012146746 | M21: =LN(F21/F22) -> 0.0016163797 | N21: =LN(G21/G22) -> 0.0020772175 | P21: NVDA | Q21: 0.046062889 | R21: 0.24387908 | S21: 0.1103628 | T21: 0.031356534 | U21: 0.016673098 | V21: 0.04761906 | X21: with short-selling | AA21: without short-selling)
A22: 46001 | B22: 278.78 | C22: 183.78 | D22: 451.45 | E22: 48.04 | F22: 37.09 | G22: 6886.68 | I22: =LN(B22/B23) -> 0.0057558257 | J22: =LN(C22/C23) -> -0.0064542597 | K22: =LN(D22/D23) -> 0.014008393 | L22: =LN(E22/E23) -> 0.0073122649 | M22: =LN(F22/F23) -> 0.019603133 | N22: =LN(G22/G23) -> 0.0067268209 | P22: TSLA | Q22: 0.065744437 | R22: 0.1103628 | S22: 0.35247395 | T22: 0.047023567 | U22: 0.024466287 | V22: 0.051530504 | X22: Portfolio Variance | Y22: {=MMULT(Y18:AC18,MMULT(Q20:U24,TRANSPOSE(Y18:AC18)))} -> 0.16516753 | AA22: Portfolio Variance | AB22: {=MMULT(Y19:AC19,MMULT(Q20:U24,TRANSPOSE(Y19:AC19)))} -> 0.12947979
A23: 46000 | B23: 277.18 | C23: 184.97 | D23: 445.17 | E23: 47.69 | F23: 36.37 | G23: 6840.51 | I23: =LN(B23/B24) -> -0.0025582373 | J23: =LN(C23/C24) -> -0.0031307377 | K23: =LN(D23/D24) -> 0.012636506 | L23: =LN(E23/E24) -> 0.0063104963 | M23: =LN(F23/F24) -> 0.00055005502 | N23: =LN(G23/G24) -> -0.00087674313 | P23: BKR | Q23: 0.019695495 | R23: 0.031356534 | S23: 0.047023567 | T23: 0.092075444 | U23: 0.022400846 | V23: 0.022423399 | X23: Portfolio Volatility | Y23: =SQRT(Y22) -> 0.40640808 | AA23: Portfolio Volatility | AB23: =SQRT(AB22) -> 0.359833
A24: 45999 | B24: 277.89 | C24: 185.55 | D24: 439.58 | E24: 47.39 | F24: 36.35 | G24: 6846.51 | I24: =LN(B24/B25) -> -0.0031975884 | J24: =LN(C24/C25) -> 0.017067487 | K24: =LN(D24/D25) -> -0.034477693 | L24: =LN(E24/E25) -> -0.037482388 | M24: =LN(F24/F25) -> 0.0013764627 | N24: =LN(G24/G25) -> -0.0034832953 | P24: CSX | Q24: 0.017611395 | R24: 0.016673098 | S24: 0.024466287 | T24: 0.022400846 | U24: 0.047314682 | V24: 0.016329415 | X24: Total Return | Y24: =SUMPRODUCT(Y18:AC18,Q4:U4) -> 0.69294828 | AA24: Total Return | AB24: =SUMPRODUCT(Q4:U4,Y19:AC19) -> 0.61610135
A25: 45996 | B25: 278.78 | C25: 182.41 | D25: 455 | E25: 49.2 | F25: 36.3 | G25: 6870.4 | I25: =LN(B25/B26) -> -0.0068635431 | J25: =LN(C25/C26) -> -0.0053036019 | K25: =LN(D25/D26) -> 0.0010335009 | L25: =LN(E25/E26) -> -0.028255562 | M25: =LN(F25/F26) -> 0.0033112613 | N25: =LN(G25/G26) -> 0.0019348002 | P25: S&P500 | Q25: 0.025817672 | R25: 0.04761906 | S25: 0.051530504 | T25: 0.022423399 | U25: 0.016329415 | V25: 0.022330027 | X25: Excess Return | Y25: =Y24-AH2 -> 0.65254828 | AA25: Excess Return | AB25: =AB24-AH2 -> 0.57570135
A26: 45995 | B26: 280.7 | C26: 183.38 | D26: 454.53 | E26: 50.61 | F26: 36.18 | G26: 6857.12 | I26: =LN(B26/B27) -> -0.012215784 | J26: =LN(C26/C27) -> 0.020884028 | K26: =LN(D26/D27) -> 0.017287148 | L26: =LN(E26/E27) -> 0.0023738884 | M26: =LN(F26/F27) -> 0.0063773958 | N26: =LN(G26/G27) -> 0.001079753 | X26: Sharp Ratio | Y26: =Y25/Y23 -> 1.6056479 | AA26: Sharp Ratio | AB26: =AB25/AB23 -> 1.5999126
A27: 45994 | B27: 284.15 | C27: 179.59 | D27: 446.74 | E27: 50.49 | F27: 35.95 | G27: 6849.72 | I27: =LN(B27/B28) -> -0.0071536582 | J27: =LN(C27/C28) -> -0.010358769 | K27: =LN(D27/D28) -> 0.039960567 | L27: =LN(E27/E28) -> 0.020206749 | M27: =LN(F27/F28) -> 0.027638533 | N27: =LN(G27/G28) -> 0.0029753463
A28: 45993 | B28: 286.19 | C28: 181.46 | D28: 429.24 | E28: 49.48 | F28: 34.97 | G28: 6829.37 | I28: =LN(B28/B29) -> 0.010855734 | J28: =LN(C28/C29) -> 0.0085229361 | K28: =LN(D28/D29) -> -0.002094534 | L28: =LN(E28/E29) -> -0.013649349 | M28: =LN(F28/F29) -> 0.0034374139 | N28: =LN(G28/G29) -> 0.0024541868 | P28: correlation | X28: Equal-Weighted Portfolio (benchmark)
A29: 45992 | B29: 283.1 | C29: 179.92 | D29: 430.14 | E29: 50.16 | F29: 34.85 | G29: 6812.63 | I29: =LN(B29/B30) -> 0.015126189 | J29: =LN(C29/C30) -> 0.016362575 | K29: =LN(D29/D30) -> -6.9742302e-05 | L29: =LN(E29/E30) -> -0.00079713037 | M29: =LN(F29/F30) -> -0.014528101 | N29: =LN(G29/G30) -> -0.0053375544 | Q29: AAPL | R29: NVDA | S29: TSLA | T29: BKR | U29: CSX
A30: 45989 | B30: 278.85 | C30: 177 | D30: 430.17 | E30: 50.2 | F30: 35.36 | G30: 6849.09 | I30: =LN(B30/B31) -> 0.0046729057 | J30: =LN(C30/C31) -> -0.018250521 | K30: =LN(D30/D31) -> 0.0083805568 | L30: =LN(E30/E31) -> 0.01343648 | M30: =LN(F30/F31) -> 0.0016982738 | N30: =LN(G30/G31) -> 0.0053404901 | P30: AAPL | Q30: 1 | R30: 0.36792336 | S30: 0.43680638 | T30: 0.25602858 | U30: 0.31936644 | Y30: AAPL | Z30: NVDA | AA30: TSLA | AB30: BKR | AC30: CSX
A31: 45987 | B31: 277.55 | C31: 180.26 | D31: 426.58 | E31: 49.53 | F31: 35.3 | G31: 6812.61 | I31: =LN(B31/B32) -> 0.0020919001 | J31: =LN(C31/C32) -> 0.01362845 | K31: =LN(D31/D32) -> 0.016974804 | L31: =LN(E31/E32) -> 0.0020210193 | M31: =LN(F31/F32) -> 0.011396135 | N31: =LN(G31/G32) -> 0.0068829722 | P31: NVDA | Q31: 0.36792336 | R31: 1 | S31: 0.37641933 | T31: 0.20925163 | U31: 0.15521407 | X31: weights | Y31: 0.2 | Z31: 0.2 | AA31: 0.2 | AB31: 0.2 | AC31: 0.2 | AD31: =SUM(Y31:AC31) -> 1
A32: 45986 | B32: 276.97 | C32: 177.82 | D32: 419.4 | E32: 49.43 | F32: 34.9 | G32: 6765.88 | I32: =LN(B32/B33) -> 0.0037982284 | J32: =LN(C32/C33) -> -0.026252305 | K32: =LN(D32/D33) -> 0.0038701403 | L32: =LN(E32/E33) -> 0.0014171477 | M32: =LN(F32/F33) -> 0.014721005 | N32: =LN(G32/G33) -> 0.0090209208 | P32: TSLA | Q32: 0.43680638 | R32: 0.37641933 | S32: 1 | T32: 0.26102382 | U32: 0.18945522
A33: 45985 | B33: 275.92 | C33: 182.55 | D33: 417.78 | E33: 49.36 | F33: 34.39 | G33: 6705.12 | I33: =LN(B33/B34) -> 0.016185662 | J33: =LN(C33/C34) -> 0.020308918 | K33: =LN(D33/D34) -> 0.066017266 | L33: =LN(E33/E34) -> 0.0097720647 | M33: =LN(F33/F34) -> 0.0032037307 | N33: =LN(G33/G34) -> 0.015348837 | P33: BKR | Q33: 0.25602858 | R33: 0.20925163 | S33: 0.26102382 | T33: 1 | U33: 0.33938649
A34: 45982 | B34: 271.49 | C34: 178.88 | D34: 391.09 | E34: 48.88 | F34: 34.28 | G34: 6602.99 | I34: =LN(B34/B35) -> 0.019489589 | J34: =LN(C34/C35) -> -0.0097909104 | K34: =LN(D34/D35) -> -0.010530161 | L34: =LN(E34/E35) -> 0.016710033 | M34: =LN(F34/F35) -> 0.017657904 | N34: =LN(G34/G35) -> 0.0097750317 | P34: CSX | Q34: 0.31936644 | R34: 0.15521407 | S34: 0.18945522 | T34: 0.33938649 | U34: 1 | X34: Portfolio Variance | Y34: {=MMULT(Y31:AC31,MMULT(Q20:U24,TRANSPOSE(Y31:AC31)))} -> 0.064112342
A35: 45981 | B35: 266.25 | C35: 180.64 | D35: 395.23 | E35: 48.07 | F35: 33.68 | G35: 6538.76 | I35: =LN(B35/B36) -> -0.0086386356 | J35: =LN(C35/C36) -> -0.032032372 | K35: =LN(D35/D36) -> -0.021922251 | L35: =LN(E35/E36) -> -0.0084930599 | M35: =LN(F35/F36) -> -0.0082791721 | N35: =LN(G35/G36) -> -0.015689667 | X35: Portfolio Volatility | Y35: =SQRT(Y34) -> 0.25320415
A36: 45980 | B36: 268.56 | C36: 186.52 | D36: 403.99 | E36: 48.48 | F36: 33.96 | G36: 6642.16 | I36: =LN(B36/B37) -> 0.0041791106 | J36: =LN(C36/C37) -> 0.028054466 | K36: =LN(D36/D37) -> 0.0068054507 | L36: =LN(E36/E37) -> 0.0087011115 | M36: =LN(F36/F37) -> -0.00088300226 | N36: =LN(G36/G37) -> 0.0037467576 | X36: Total Return | Y36: =SUMPRODUCT(Y31:AC31,Q4:U4) -> 0.3379622
A37: 45979 | B37: 267.44 | C37: 181.36 | D37: 401.25 | E37: 48.06 | F37: 33.99 | G37: 6617.32 | I37: =LN(B37/B38) -> -7.4780333e-05 | J37: =LN(C37/C38) -> -0.028483282 | K37: =LN(D37/D38) -> -0.018934863 | L37: =LN(E37/E38) -> 0.0037523496 | M37: =LN(F37/F38) -> -0.00058823531 | N37: =LN(G37/G38) -> -0.0082906599 | X37: Excess Return | Y37: =Y36-AH2 -> 0.2975622
A38: 45978 | B38: 267.46 | C38: 186.6 | D38: 408.92 | E38: 47.88 | F38: 34.01 | G38: 6672.41 | I38: =LN(B38/B39) -> -0.018338262 | J38: =LN(C38/C39) -> -0.018951121 | K38: =LN(D38/D39) -> 0.011238698 | L38: =LN(E38/E39) -> -0.017596976 | M38: =LN(F38/F39) -> -0.02583223 | N38: =LN(G38/G39) -> -0.0092045416 | X38: Sharp Ratio | Y38: =Y37/Y35 -> 1.1751869
A39: 45975 | B39: 272.41 | C39: 190.17 | D39: 404.35 | E39: 48.73 | F39: 34.9 | G39: 6734.11 | I39: =LN(B39/B40) -> -0.0019803439 | J39: =LN(C39/C40) -> 0.017558736 | K39: =LN(D39/D40) -> 0.0058536269 | L39: =LN(E39/E40) -> 0.025354642 | M39: =LN(F39/F40) -> 0.00057323017 | N39: =LN(G39/G40) -> -0.00050179638
A40: 45974 | B40: 272.95 | C40: 186.86 | D40: 401.99 | E40: 47.51 | F40: 34.88 | G40: 6737.49 | I40: =LN(B40/B41) -> -0.0019032984 | J40: =LN(C40/C41) -> -0.036467026 | K40: =LN(D40/D41) -> -0.068752372 | L40: =LN(E40/E41) -> -0.00042087543 | M40: =LN(F40/F41) -> -0.014515695 | N40: =LN(G40/G41) -> -0.016695498
...

Sheet  Risk–return profiles& (heatmp)
A1: Ticker | B1: Annual Returns | C1: Annual Volatility
A2: AAPL | B2: 0.230652 | C2: 0.2536854
A3: NVDA | B3: 0.82817517 | C3: 0.49416983
A4: TSLA | B4: 0.43282682 | C4: 0.59409031
A5: BKR | B5: 0.16654041 | C5: 0.30364131
A6: CSX | B6: 0.031616622 | C6: 0.21766415
C18: Correlation Heatmap
A19: correlation
B20: AAPL | C20: NVDA | D20: TSLA | E20: BKR | F20: CSX
A21: AAPL | B21: 1 | C21: 0.36792336 | D21: 0.43680638 | E21: 0.25602858 | F21: 0.31936644
A22: NVDA | B22: 0.36792336 | C22: 1 | D22: 0.37641933 | E22: 0.20925163 | F22: 0.15521407
A23: TSLA | B23: 0.43680638 | C23: 0.37641933 | D23: 1 | E23: 0.26102382 | F23: 0.18945522
A24: BKR | B24: 0.25602858 | C24: 0.20925163 | D24: 0.26102382 | E24: 1 | F24: 0.33938649
A25: CSX | B25: 0.31936644 | C25: 0.15521407 | D25: 0.18945522 | E25: 0.33938649 | F25: 1

Sheet Robust Max sharp Portfolio
A1: Robust Max Sharpe Portfolio (Min Weight 5%,Max weight 30%)
B3: AAPL | C3: NVDA | D3: TSLA | E3: BKR | F3: CSX
A4: weights (with short-selling) | B4: 0.28750924 | C4: 0.29400141 | D4: 0.05 | E4: 0.28750924 | F4: 0.080980103 | G4: =SUM(B4:F4) -> 1
A6: Portfolio Variance | B6: 0.16516753
A7: Portfolio Volatility | B7: 0.40640808
A8: Total Return | B8: 0.69294828
A9: Excess Return | B9: 0.65254828
A10: Sharp Ratio | B10: =B9/B7 -> 1.6056479

Sheet  Rolling-window portfolio analy
A1: log return | L1: Daily Risk free rate | N1: =4.04%/252 -> 0.00016031746
A2: Date | B2: AAPL | C2: NVDA | D2: TSLA | E2: BKR | F2: CSX | G2: S&P500 | H2: MSR PORTFOLIO(without short-selling) | I2: Beta for the previous 60 days only. | J2: Rolling Alpha
A3: 46030 | B3: -0.0049675671 | C3: -0.021756838 | D3: 0.010124508 | E3: 0.027465377 | F3: 0.0076737623 | G3: 7.6576372e-05 | H3: =(Sheet1!$Y$19*' Rolling-window portfolio analy'!B3+Sheet1!$Z$19*' Rolling-window portfolio analy'!C3+Sheet1!$AA$19*' Rolling-window portfolio analy'!D3+Sheet1!$AB$19*' Rolling-window portfolio analy'!E3+Sheet1!$AC$19*' Rolling-window portfolio analy'!F3) -> -0.01285456
A4: 46029 | B4: -0.0077675494 | C4: 0.0099376399 | D4: -0.003586431 | E4: -0.010995835 | F4: -0.028685881 | G4: -0.0034459043 | H4: =(Sheet1!$Y$19*' Rolling-window portfolio analy'!B4+Sheet1!$Z$19*' Rolling-window portfolio analy'!C4+Sheet1!$AA$19*' Rolling-window portfolio analy'!D4+Sheet1!$AB$19*' Rolling-window portfolio analy'!E4+Sheet1!$AC$19*' Rolling-window portfolio analy'!F4) -> 0.0035243742
A5: 46028 | B5: -0.018504361 | C5: -0.0046888406 | D5: -0.04230648 | E5: 0.0062976338 | F5: 0.0044456867 | G5: 0.006177589 | H5: =(Sheet1!$Y$19*' Rolling-window portfolio analy'!B5+Sheet1!$Z$19*' Rolling-window portfolio analy'!C5+Sheet1!$AA$19*' Rolling-window portfolio analy'!D5+Sheet1!$AB$19*' Rolling-window portfolio analy'!E5+Sheet1!$AC$19*' Rolling-window portfolio analy'!F5) -> -0.0071505596
A6: 46027 | B6: -0.013933753 | C6: -0.0038729921 | D6: 0.03057311 | E6: 0.040125953 | F6: -0.0099751451 | G6: 0.0063340841 | H6: =(Sheet1!$Y$19*' Rolling-window portfolio analy'!B6+Sheet1!$Z$19*' Rolling-window portfolio analy'!C6+Sheet1!$AA$19*' Rolling-window portfolio analy'!D6+Sheet1!$AB$19*' Rolling-window portfolio analy'!E6+Sheet1!$AC$19*' Rolling-window portfolio analy'!F6) -> -0.0021386807
A7: 46024 | B7: -0.0031315073 | C7: 0.01252181 | D7: -0.026246452 | E7: 0.034530837 | F7: 0.00055157199 | G7: 0.0018928827 | H7: =(Sheet1!$Y$19*' Rolling-window portfolio analy'!B7+Sheet1!$Z$19*' Rolling-window portfolio analy'!C7+Sheet1!$AA$19*' Rolling-window portfolio analy'!D7+Sheet1!$AB$19*' Rolling-window portfolio analy'!E7+Sheet1!$AC$19*' Rolling-window portfolio analy'!F7) -> 0.010646584
A8: 46022 | B8: -0.0044775646 | C8: -0.0055609169 | D8: -0.010418719 | E8: -0.012004946 | F8: -0.004678693 | G8: -0.0073848334 | H8: =(Sheet1!$Y$19*' Rolling-window portfolio analy'!B8+Sheet1!$Z$19*' Rolling-window portfolio analy'!C8+Sheet1!$AA$19*' Rolling-window portfolio analy'!D8+Sheet1!$AB$19*' Rolling-window portfolio analy'!E8+Sheet1!$AC$19*' Rolling-window portfolio analy'!F8) -> -0.0059116019
A9: 46021 | B9: -0.0024870176 | C9: -0.0036193354 | D9: -0.011399688 | E9: 0.015524527 | F9: -0.0082034915 | G9: -0.0013766143 | H9: =(Sheet1!$Y$19*' Rolling-window portfolio analy'!B9+Sheet1!$Z$19*' Rolling-window portfolio analy'!C9+Sheet1!$AA$19*' Rolling-window portfolio analy'!D9+Sheet1!$AB$19*' Rolling-window portfolio analy'!E9+Sheet1!$AC$19*' Rolling-window portfolio analy'!F9) -> -0.0015358569
A10: 46020 | B10: 0.0013158859 | C10: -0.012198171 | D10: -0.03327115 | E10: 0.0028688092 | F10: 0.0027270265 | G10: -0.0034982053 | H10: =(Sheet1!$Y$19*' Rolling-window portfolio analy'!B10+Sheet1!$Z$19*' Rolling-window portfolio analy'!C10+Sheet1!$AA$19*' Rolling-window portfolio analy'!D10+Sheet1!$AB$19*' Rolling-window portfolio analy'!E10+Sheet1!$AC$19*' Rolling-window portfolio analy'!F10) -> -0.0074464142
A11: 46017 | B11: -0.0014985109 | C11: 0.010128271 | D11: -0.021258569 | E11: -0.0011043623 | F11: -0.0043596799 | G11: -0.0003044296 | H11: =(Sheet1!$Y$19*' Rolling-window portfolio analy'!B11+Sheet1!$Z$19*' Rolling-window portfolio analy'!C11+Sheet1!$AA$19*' Rolling-window portfolio analy'!D11+Sheet1!$AB$19*' Rolling-window portfolio analy'!E11+Sheet1!$AC$19*' Rolling-window portfolio analy'!F11) -> 0.0061144319
A12: 46015 | B12: 0.0053097146 | C12: -0.0031761183 | D12: -0.00032957074 | E12: 0.0024312091 | F12: 0.0051792401 | G12: 0.0032163382 | H12: =(Sheet1!$Y$19*' Rolling-window portfolio analy'!B12+Sheet1!$Z$19*' Rolling-window portfolio analy'!C12+Sheet1!$AA$19*' Rolling-window portfolio analy'!D12+Sheet1!$AB$19*' Rolling-window portfolio analy'!E12+Sheet1!$AC$19*' Rolling-window portfolio analy'!F12) -> -0.00052876147
A13: 46014 | B13: 0.005116607 | C13: 0.029607955 | D13: -0.0065073257 | E13: -0.0081543152 | F13: 0.0013674281 | G13: 0.0045400955 | H13: =(Sheet1!$Y$19*' Rolling-window portfolio analy'!B13+Sheet1!$Z$19*' Rolling-window portfolio analy'!C13+Sheet1!$AA$19*' Rolling-window portfolio analy'!D13+Sheet1!$AB$19*' Rolling-window portfolio analy'!E13+Sheet1!$AC$19*' Rolling-window portfolio analy'!F13) -> 0.019869725
A14: 46013 | B14: -0.0099148873 | C14: 0.014807773 | D14: 0.015527206 | E14: 0.018832948 | F14: 0.0010952904 | G14: 0.0064158365 | H14: =(Sheet1!$Y$19*' Rolling-window portfolio analy'!B14+Sheet1!$Z$19*' Rolling-window portfolio analy'!C14+Sheet1!$AA$19*' Rolling-window portfolio analy'!D14+Sheet1!$AB$19*' Rolling-window portfolio analy'!E14+Sheet1!$AC$19*' Rolling-window portfolio analy'!F14) -> 0.0090428141
... A61: 45945 | B61: 0.0063165304 | C61: -0.0011115435 | D61: 0.013674596 | E61: -0.0080627536 | F61: 0.003039936 | G61: 0.0040179185 | H61: =(Sheet1!$Y$19*' Rolling-window portfolio analy'!B61+Sheet1!$Z$19*' Rolling-window portfolio analy'!C61+Sheet1!$AA$19*' Rolling-window portfolio analy'!D61+Sheet1!$AB$19*' Rolling-window portfolio analy'!E61+Sheet1!$AC$19*' Rolling-window portfolio analy'!F61) -> 0.00010310882
A62: 45944 | B62: 0.0004440587 | C62: -0.04501914 | D62: -0.015396656 | E62: -0.014614963 | F62: 0.015620959 | G62: -0.001565528 | H62: =(Sheet1!$Y$19*' Rolling-window portfolio analy'!B62+Sheet1!$Z$19*' Rolling-window portfolio analy'!C62+Sheet1!$AA$19*' Rolling-window portfolio analy'!D62+Sheet1!$AB$19*' Rolling-window portfolio analy'!E62+Sheet1!$AC$19*' Rolling-window portfolio analy'!F62) -> -0.030775345 | I62: =SLOPE(H3:H62,G3:G62) -> 1.4227262 | J62: =AVERAGE(H3:H62)-($N$1+I62*(AVERAGE(G3:G62)-$N$1)) -> -0.00071386956
A63: 45943 | B63: 0.0096971932 | C63: 0.027782556 | D63: 0.052779529 | E63: 0.0099415378 | F63: 0.0022516193 | G63: 0.015478195 | H63: =(Sheet1!$Y$19*' Rolling-window portfolio analy'!B63+Sheet1!$Z$19*' Rolling-window portfolio analy'!C63+Sheet1!$AA$19*' Rolling-window portfolio analy'!D63+Sheet1!$AB$19*' Rolling-window portfolio analy'!E63+Sheet1!$AC$19*' Rolling-window portfolio analy'!F63) -> 0.021637964 | I63: =SLOPE(H4:H63,G4:G63) -> 1.421369 | J63: =AVERAGE(H4:H63)-($N$1+I63*(AVERAGE(G4:G63)-$N$1)) -> -0.00050317915
A64: 45940 | B64: -0.03513209 | C64: -0.050099636 | D64: -0.05195331 | E64: -0.061355731 | F64: -0.015655897 | G64: -0.02748596 | H64: =(Sheet1!$Y$19*' Rolling-window portfolio analy'!B64+Sheet1!$Z$19*' Rolling-window portfolio analy'!C64+Sheet1!$AA$19*' Rolling-window portfolio analy'!D64+Sheet1!$AB$19*' Rolling-window portfolio analy'!E64+Sheet1!$AC$19*' Rolling-window portfolio analy'!F64) -> -0.047448591 | I64: =SLOPE(H5:H64,G5:G64) -> 1.4849623 | J64: =AVERAGE(H5:H64)-($N$1+I64*(AVERAGE(G5:G64)-$N$1)) -> -0.00080553517
A65: 45939 | B65: -0.015700381 | C65: 0.018130868 | D65: -0.0072063728 | E65: 0.00083559646 | F65: 0.0027777796 | G65: -0.0027593219 | H65: =(Sheet1!$Y$19*' Rolling-window portfolio analy'!B65+Sheet1!$Z$19*' Rolling-window portfolio analy'!C65+Sheet1!$AA$19*' Rolling-window portfolio analy'!D65+Sheet1!$AB$19*' Rolling-window portfolio analy'!E65+Sheet1!$AC$19*' Rolling-window portfolio analy'!F65) -> 0.0080310297 | I65: =SLOPE(H6:H65,G6:G65) -> 1.497334 | J65: =AVERAGE(H6:H65)-($N$1+I65*(AVERAGE(G6:G65)-$N$1)) -> -0.00033382195
A66: 45938 | B66: 0.0061414272 | C66: 0.021756838 | D66: 0.012847455 | E66: -0.015140806 | F66: -0.0011120379 | G66: 0.0058106934 | H66: =(Sheet1!$Y$19*' Rolling-window portfolio analy'!B66+Sheet1!$Z$19*' Rolling-window portfolio analy'!C66+Sheet1!$AA$19*' Rolling-window portfolio analy'!D66+Sheet1!$AB$19*' Rolling-window portfolio analy'!E66+Sheet1!$AC$19*' Rolling-window portfolio analy'!F66) -> 0.01435726 | I66: =SLOPE(H7:H66,G7:G66) -> 1.5225698 | J66: =AVERAGE(H7:H66)-($N$1+I66*(AVERAGE(G7:G66)-$N$1)) -> -5.069967e-05
A67: 45937 | B67: -0.00081844228 | C67: -0.0026984743 | D67: -0.045498291 | E67: -0.010239696 | F67: -0.0071982592 | G67: -0.0038186963 | H67: =(Sheet1!$Y$19*' Rolling-window portfolio analy'!B67+Sheet1!$Z$19*' Rolling-window portfolio analy'!C67+Sheet1!$AA$19*' Rolling-window portfolio analy'!D67+Sheet1!$AB$19*' Rolling-window portfolio analy'!E67+Sheet1!$AC$19*' Rolling-window portfolio analy'!F67) -> -0.0030239333 | I67: =SLOPE(H8:H67,G8:G67) -> 1.5163353 | J67: =AVERAGE(H8:H67)-($N$1+I67*(AVERAGE(G8:G67)-$N$1)) -> -0.00013299362
A68: 45936 | B68: -0.0051679702 | C68: -0.011148148 | D68: 0.053054068 | E68: 0.011887822 | F68: 0.0066427036 | G68: 0.003639997 | H68: =(Sheet1!$Y$19*' Rolling-window portfolio analy'!B68+Sheet1!$Z$19*' Rolling-window portfolio analy'!C68+Sheet1!$AA$19*' Rolling-window portfolio analy'!D68+Sheet1!$AB$19*' Rolling-window portfolio analy'!E68+Sheet1!$AC$19*' Rolling-window portfolio analy'!F68) -> -0.0073593316 | I68: =SLOPE(H9:H68,G9:G68) -> 1.5169874 | J68: =AVERAGE(H9:H68)-($N$1+I68*(AVERAGE(G9:G68)-$N$1)) -> -0.0004359284
A69: 45933 | B69: 0.0034553077 | C69: -0.0067461943 | D69: -0.014252462 | E69: 0.0020639842 | F69: 0.012294092 | G69: 6.5519383e-05 | H69: =(Sheet1!$Y$19*' Rolling-window portfolio analy'!B69+Sheet1!$Z$19*' Rolling-window portfolio analy'!C69+Sheet1!$AA$19*' Rolling-window portfolio analy'!D69+Sheet1!$AB$19*' Rolling-window portfolio analy'!E69+Sheet1!$AC$19*' Rolling-window portfolio analy'!F69) -> -0.0033871319 | I69: =SLOPE(H10:H69,G10:G69) -> 1.5177917 | J69: =AVERAGE(H10:H69)-($N$1+I69*(AVERAGE(G10:G69)-$N$1)) -> -0.00050349046
A70: 45932 | B70: 0.0065550978 | C70: 0.0087736186 | D70: -0.052409644 | E70: 0.00082678798 | F70: 0.016154524 | G70: 0.00061817818 | H70: =(Sheet1!$Y$19*' Rolling-window portfolio analy'!B70+Sheet1!$Z$19*' Rolling-window portfolio analy'!C70+Sheet1!$AA$19*' Rolling-window portfolio analy'!D70+Sheet1!$AB$19*' Rolling-window portfolio analy'!E70+Sheet1!$AC$19*' Rolling-window portfolio analy'!F70) -> 0.0073571032 | I70: =SLOPE(H11:H70,G11:G70) -> 1.5163446 | J70: =AVERAGE(H11:H70)-($N$1+I70*(AVERAGE(G11:G70)-$N$1)) -> -0.0003603538
A71: 45931 | B71: 0.0032151847 | C71: 0.0035311149 | D71: 0.032607016 | E71: -0.0074165977 | F71: -0.014466285 | G71: 0.0033941192 | H71: =(Sheet1!$Y$19*' Rolling-window portfolio analy'!B71+Sheet1!$Z$19*' Rolling-window portfolio analy'!C71+Sheet1!$AA$19*' Rolling-window portfolio analy'!D71+Sheet1!$AB$19*' Rolling-window portfolio analy'!E71+Sheet1!$AC$19*' Rolling-window portfolio analy'!F71) -> 0.0024667737 | I71: =SLOPE(H12:H71,G12:G71) -> 1.5163607 | J71: =AVERAGE(H12:H71)-($N$1+I71*(AVERAGE(G12:G71)-$N$1)) -> -0.00051462639
A72: 45930 | B72: 0.00078576203 | C72: 0.02567793 | D72: 0.0034011723 | E72: -0.036873322 | F72: -0.0089711844 | G72: 0.0040825036 | H72: =(Sheet1!$Y$19*' Rolling-window portfolio analy'!B72+Sheet1!$Z$19*' Rolling-window portfolio analy'!C72+Sheet1!$AA$19*' Rolling-window portfolio analy'!D72+Sheet1!$AB$19*' Rolling-window portfolio analy'!E72+Sheet1!$AC$19*' Rolling-window portfolio analy'!F72) -> 0.013513619 | I72: =SLOPE(H13:H72,G13:G72) -> 1.526551 | J72: =AVERAGE(H13:H72)-($N$1+I72*(AVERAGE(G13:G72)-$N$1)) -> -0.00030706588
A73: 45929 | B73: -0.0040400926 | C73: 0.020331775 | D73: 0.0063602935 | E73: 0.00059364798 | F73: 0.052130932 | G73: 0.0026321125 | H73: =(Sheet1!$Y$19*' Rolling-window portfolio analy'!B73+Sheet1!$Z$19*' Rolling-window portfolio analy'!C73+Sheet1!$AA$19*' Rolling-window portfolio analy'!D73+Sheet1!$AB$19*' Rolling-window portfolio analy'!E73+Sheet1!$AC$19*' Rolling-window portfolio analy'!F73) -> 0.012373202 | I73: =SLOPE(H14:H73,G14:G73) -> 1.5176541 | J73: =AVERAGE(H14:H73)-($N$1+I73*(AVERAGE(G14:G73)-$N$1)) -> -0.00037974052
... A754: 44936 | B754: 0.0044464961 | C754: 0.017755698 | D754: -0.0077110432 | E754: 0.010747539 | F754: 0.0080570625 | G754: 0.0069540206 | H754: =(Sheet1!$Y$19*' Rolling-window portfolio analy'!B754+Sheet1!$Z$19*' Rolling-window portfolio analy'!C754+Sheet1!$AA$19*' Rolling-window portfolio analy'!D754+Sheet1!$AB$19*' Rolling-window portfolio analy'!E754+Sheet1!$AC$19*' Rolling-window portfolio analy'!F754) -> 0.013734944 | I754: =SLOPE(H695:H754,G695:G754) -> 1.694558 | J754: =AVERAGE(H695:H754)-($N$1+I754*(AVERAGE(G695:G754)-$N$1)) -> 0.0055093155
